[2020-06-05 19:19:49,347] {taskinstance.py:669} INFO - Dependencies all met for <TaskInstance: first_dag.download_images 2020-06-03T00:00:00+00:00 [queued]>
[2020-06-05 19:19:49,353] {taskinstance.py:669} INFO - Dependencies all met for <TaskInstance: first_dag.download_images 2020-06-03T00:00:00+00:00 [queued]>
[2020-06-05 19:19:49,354] {taskinstance.py:879} INFO - 
--------------------------------------------------------------------------------
[2020-06-05 19:19:49,354] {taskinstance.py:880} INFO - Starting attempt 2 of 2
[2020-06-05 19:19:49,354] {taskinstance.py:881} INFO - 
--------------------------------------------------------------------------------
[2020-06-05 19:19:49,363] {taskinstance.py:900} INFO - Executing <Task(BashOperator): download_images> on 2020-06-03T00:00:00+00:00
[2020-06-05 19:19:49,366] {standard_task_runner.py:53} INFO - Started process 15758 to run task
[2020-06-05 19:19:49,416] {logging_mixin.py:112} INFO - Running %s on host %s <TaskInstance: first_dag.download_images 2020-06-03T00:00:00+00:00 [running]> airflow.us-central1-a.c.greenr-276821.internal
[2020-06-05 19:19:49,427] {bash_operator.py:82} INFO - Tmp dir root location: 
 /tmp
[2020-06-05 19:19:49,428] {bash_operator.py:105} INFO - Temporary script location: /tmp/airflowtmpt0zsno23/download_images3tp36fgn
[2020-06-05 19:19:49,428] {bash_operator.py:115} INFO - Running command: python /Users/binhphan/airflow/scripts/download_images.py
[2020-06-05 19:19:49,434] {bash_operator.py:122} INFO - Output:
[2020-06-05 19:19:49,445] {bash_operator.py:126} INFO - python: can't open file '/Users/binhphan/airflow/scripts/download_images.py': [Errno 2] No such file or directory
[2020-06-05 19:19:49,445] {bash_operator.py:130} INFO - Command exited with return code 2
[2020-06-05 19:19:49,452] {taskinstance.py:1145} ERROR - Bash command failed
Traceback (most recent call last):
  File "/usr/local/lib/python3.6/dist-packages/airflow/models/taskinstance.py", line 983, in _run_raw_task
    result = task_copy.execute(context=context)
  File "/usr/local/lib/python3.6/dist-packages/airflow/operators/bash_operator.py", line 134, in execute
    raise AirflowException("Bash command failed")
airflow.exceptions.AirflowException: Bash command failed
[2020-06-05 19:19:49,454] {taskinstance.py:1187} INFO - All retries failed; marking task as FAILED.dag_id=first_dag, task_id=download_images, execution_date=20200603T000000, start_date=20200605T191949, end_date=20200605T191949
[2020-06-05 19:19:59,344] {logging_mixin.py:112} INFO - [2020-06-05 19:19:59,343] {local_task_job.py:103} INFO - Task exited with return code 1
